<?xml version="1.0"?>
<robot xmlns:xacro="http://www.ros.org/wiki/xacro" name="scout_mini">

  <xacro:property name="PI" value="3.1415926535897931" />

  <link name="base_link">
    <visual>
      <origin xyz="0 0 0.0" rpy="${PI/2} 0 -${PI/2}" />
      <geometry>
        <mesh filename="package://scout_mini_description/meshes/body.dae" />
      </geometry>
    </visual>
    <collision>
      <origin xyz="0 0 0" rpy="0 0 0" />
      <geometry>
        <box size="0.514618 0.3816 0.10357" />
      </geometry>
    </collision>
  </link>

  <joint name="inertial_joint" type="fixed">
    <parent link="base_link" />
    <child link="inertial_link" />
    <origin xyz="0 0 0" rpy="0 0 0" />
  </joint>

  <link name="inertial_link">
    <inertial>
      <mass value="60" />
      <origin xyz="0 0 0" rpy="0 0 0" />
      <inertia ixx="2.288641" ixy="0" ixz="0" iyy="5.103976" iyz="0" izz="3.431465" />
    </inertial>
  </link>

  <joint name="front_left_wheel_joint" type="continuous">
    <parent link="base_link" />
    <child link="front_left_wheel_link" />
    <origin xyz="0.2319755 0.245 -0.100998" rpy="0 0 0" />
    <axis xyz="0 1 0" rpy="0 0 0" />
  </joint>

  <link name="front_left_wheel_link">
    <visual>
      <origin xyz="0 -0.0367485 0" rpy="-${PI/2} 0 0" />
      <geometry>
        <mesh filename="package://scout_mini_description/meshes/wheel.dae" />
      </geometry>
    </visual>
    <collision>
      <origin xyz="0 -0.0367485 0" rpy="${PI/2} 0 0" />
      <geometry>
        <cylinder length="0.08" radius="0.0875" />
      </geometry>
    </collision>
    <inertial>
      <mass value="3" />
      <origin xyz="0 0 0" rpy="0 0 0" />
      <inertia ixx="0.007" ixy="0" ixz="0" iyy="0.007" iyz="0" izz="0.012" />
    </inertial>
  </link>

  <joint name="rear_left_wheel_joint" type="continuous">
    <parent link="base_link" />
    <child link="rear_left_wheel_link" />
    <origin xyz="-0.2319755 0.245 -0.100998" rpy="0 0 0" />
    <axis xyz="0 1 0" rpy="0 0 0" />
  </joint>

  <link name="rear_left_wheel_link">
    <visual>
      <origin xyz="0 -0.0367485 0" rpy="-${PI/2} 0 0" />
      <geometry>
        <mesh filename="package://scout_mini_description/meshes/wheel.dae" />
      </geometry>
    </visual>
    <collision>
      <origin xyz="0 -0.0367485 0" rpy="${PI/2} 0 0" />
      <geometry>
        <cylinder length="0.08" radius="0.0875" />
      </geometry>
    </collision>
    <inertial>
      <mass value="3" />
      <origin xyz="0 0 0" rpy="0 0 0" />
      <inertia ixx="0.007" ixy="0" ixz="0" iyy="0.007" iyz="0" izz="0.012" />
    </inertial>
  </link>

  <joint name="front_right_wheel_joint" type="continuous">
    <parent link="base_link" />
    <child link="front_right_wheel_link" />
    <origin xyz="0.2319755 -0.245 -0.099998" rpy="0 0 0" />
    <axis xyz="0 1 0" rpy="0 0 0" />
  </joint>

  <link name="front_right_wheel_link">
    <visual>
      <origin xyz="0 0.0367485 0" rpy="${PI/2} 0 0" />
      <geometry>
        <mesh filename="package://scout_mini_description/meshes/wheel.dae" />
      </geometry>
    </visual>
    <collision>
      <origin xyz="0 0.0367485 0" rpy="${PI/2} 0 0" />
      <geometry>
        <cylinder length="0.08" radius="0.0875" />
      </geometry>
    </collision>
    <inertial>
      <mass value="3" />
      <origin xyz="0 0 0" rpy="0 0 0" />
      <inertia ixx="0.007" ixy="0" ixz="0" iyy="0.007" iyz="0" izz="0.012" />
    </inertial>
  </link>

  <joint name="rear_right_wheel_joint" type="continuous">
    <parent link="base_link" />
    <child link="rear_right_wheel_link" />
    <origin xyz="-0.2319755 -0.245 -0.099998" rpy="0 0 0" />
    <axis xyz="0 1 0" rpy="0 0 0" />
  </joint>

  <link name="rear_right_wheel_link">
    <visual>
      <origin xyz="0 0.0367485 0" rpy="${PI/2} 0 0" />
      <geometry>
        <mesh filename="package://scout_mini_description/meshes/wheel.dae" />
      </geometry>
    </visual>
    <collision>
      <origin xyz="0 0.0367485 0" rpy="${PI/2} 0 0" />
      <geometry>
        <cylinder length="0.08" radius="0.0875" />
      </geometry>
    </collision>
    <inertial>
      <mass value="3" />
      <origin xyz="0 0 0" rpy="0 0 0" />
      <inertia ixx="0.007" ixy="0" ixz="0" iyy="0.007" iyz="0" izz="0.012" />
    </inertial>
  </link>

  <gazebo>
    <plugin name='diff_drive' filename='libgazebo_ros_diff_drive.so'>
      <ros>
        <namespace>/</namespace>
      </ros>
      <left_joint>front_left_wheel_joint</left_joint>
      <right_joint>front_right_wheel_joint</right_joint>
      <left_joint>rear_left_wheel_joint</left_joint>
      <right_joint>rear_right_wheel_joint</right_joint>
      <wheel_separation>0.490</wheel_separation>
      <wheel_diameter>0.175</wheel_diameter>
      <max_wheel_torque>20</max_wheel_torque>
      <max_wheel_acceleration>1.0</max_wheel_acceleration>
      <publish_odom>true</publish_odom>
      <publish_odom_tf>true</publish_odom_tf>
      <publish_wheel_tf>true</publish_wheel_tf>
      <odometry_frame>odom</odometry_frame>
      <robot_base_frame>base_link</robot_base_frame>
    </plugin>
  </gazebo>

  <gazebo reference="front_left_wheel_link">
    <mu1>1.0</mu1> <mu2>1.0</mu2> <kp>10000000.0</kp> <kd>1.0</kd> <minDepth>0.001</minDepth>
  </gazebo>
  <gazebo reference="front_right_wheel_link">
    <mu1>1.0</mu1> <mu2>1.0</mu2> <kp>10000000.0</kp> <kd>1.0</kd> <minDepth>0.001</minDepth>
  </gazebo>
  <gazebo reference="rear_left_wheel_link">
    <mu1>1.0</mu1> <mu2>1.0</mu2> <kp>10000000.0</kp> <kd>1.0</kd> <minDepth>0.001</minDepth>
  </gazebo>
  <gazebo reference="rear_right_wheel_link">
    <mu1>1.0</mu1> <mu2>1.0</mu2> <kp>10000000.0</kp> <kd>1.0</kd> <minDepth>0.001</minDepth>
  </gazebo>

</robot>
