<?xml version="1.0"?>
<robot xmlns:xacro="http://www.ros.org/wiki/xacro" name="scout_mini">

  <xacro:property name="PI" value="3.1415926535897931" />

  <link name="base_footprint"/>
  
  <joint name="base_footprint_joint" type="fixed">
    <parent link="base_link"/>       <child link="base_footprint"/>   <origin xyz="0 0 0" rpy="0 0 0"/>
  </joint>
  <link name="base_link">
    <visual>
      <origin xyz="0 0 0.0" rpy="${PI/2} 0 -${PI/2}" />
      <geometry>
        <mesh filename="package://scout_mini_description/meshes/body.dae" />
      </geometry>
    </visual>
    <collision>
      <origin xyz="0 0 0" rpy="0 0 0" />
      <geometry>
        <box size="0.514618 0.3816 0.10357" />
      </geometry>
    </collision>
  </link>

  <joint name="inertial_joint" type="fixed">
    <parent link="base_link" />
    <child link="inertial_link" />
    <origin xyz="0 0 0" rpy="0 0 0" />
  </joint>
  <link name="inertial_link">
    <inertial>
      <mass value="10" />
      <origin xyz="0 0 0" rpy="0 0 0" />
      <inertia ixx="0.3" ixy="0" ixz="0" iyy="0.8" iyz="0" izz="0.5" />
    </inertial>
  </link>

  <xacro:macro name="wheel_link" params="prefix">
    <link name="${prefix}_link">
      <visual>
        <origin xyz="0 ${-0.0367485 if 'left' in prefix else 0.0367485} 0" rpy="${-PI/2 if 'left' in prefix else PI/2} 0 0" />
        <geometry>
          <mesh filename="package://scout_mini_description/meshes/wheel.dae" />
        </geometry>
      </visual>
      <collision>
        <origin xyz="0 ${-0.0367485 if 'left' in prefix else 0.0367485} 0" rpy="${PI/2} 0 0" />
        <geometry>
          <cylinder length="0.08" radius="0.0875" />
        </geometry>
      </collision>
      <inertial>
        <mass value="2" />
        <origin xyz="0 0 0" rpy="0 0 0" />
        <inertia ixx="0.005" ixy="0" ixz="0" iyy="0.005" iyz="0" izz="0.008" />
      </inertial>
    </link>
  </xacro:macro>

  <xacro:wheel_link prefix="front_left_wheel"/>
  <xacro:wheel_link prefix="rear_left_wheel"/>
  <xacro:wheel_link prefix="front_right_wheel"/>
  <xacro:wheel_link prefix="rear_right_wheel"/>

  <joint name="front_left_wheel_joint" type="continuous">
    <parent link="base_link" />
    <child link="front_left_wheel_link" />
    <origin xyz="0.2319755 0.245 -0.100998" rpy="0 0 0" />
    <axis xyz="0 1 0" rpy="0 0 0" />
  </joint>
  <joint name="rear_left_wheel_joint" type="continuous">
    <parent link="base_link" />
    <child link="rear_left_wheel_link" />
    <origin xyz="-0.2319755 0.245 -0.100998" rpy="0 0 0" />
    <axis xyz="0 1 0" rpy="0 0 0" />
  </joint>
  <joint name="front_right_wheel_joint" type="continuous">
    <parent link="base_link" />
    <child link="front_right_wheel_link" />
    <origin xyz="0.2319755 -0.245 -0.099998" rpy="0 0 0" />
    <axis xyz="0 1 0" rpy="0 0 0" />
  </joint>
  <joint name="rear_right_wheel_joint" type="continuous">
    <parent link="base_link" />
    <child link="rear_right_wheel_link" />
    <origin xyz="-0.2319755 -0.245 -0.099998" rpy="0 0 0" />
    <axis xyz="0 1 0" rpy="0 0 0" />
  </joint>

  <joint name="rplidar_joint" type="fixed">
    <parent link="base_link"/>
    <child link="laser_link"/>
    <origin xyz="0 0 0.45" rpy="0 0 0"/>
  </joint>
  <link name="laser_link">
    <visual>
      <origin xyz="0 0 0" rpy="0 0 0"/>
      <geometry>
        <cylinder length="0.04" radius="0.035"/>
      </geometry>
      <material name="black">
        <color rgba="0 0 0 1"/>
      </material>
    </visual>
  </link>
  
  <ros2_control name="scout_mini_control" type="system">
    <hardware>
      <plugin>scout_mini_hardware/ScoutMiniHardware</plugin>
      <param name="interface">can0</param>
      <param name="wheel_radius">0.0875</param>
      <param name="wheel_separation">0.490</param>
    </hardware>

    <joint name="front_left_wheel_joint">
      <command_interface name="velocity">
        <param name="min">-10</param>
        <param name="max">10</param>
      </command_interface>
      <state_interface name="position"/>
      <state_interface name="velocity"/>
      <state_interface name="effort"/>
    </joint>

    <joint name="rear_left_wheel_joint">
      <command_interface name="velocity">
        <param name="min">-10</param>
        <param name="max">10</param>
      </command_interface>
      <state_interface name="position"/>
      <state_interface name="velocity"/>
      <state_interface name="effort"/>
    </joint>

    <joint name="front_right_wheel_joint">
      <command_interface name="velocity">
        <param name="min">-10</param>
        <param name="max">10</param>
      </command_interface>
      <state_interface name="position"/>
      <state_interface name="velocity"/>
      <state_interface name="effort"/>
    </joint>

    <joint name="rear_right_wheel_joint">
      <command_interface name="velocity">
        <param name="min">-10</param>
        <param name="max">10</param>
      </command_interface>
      <state_interface name="position"/>
      <state_interface name="velocity"/>
      <state_interface name="effort"/>
    </joint>
  </ros2_control>

</robot>
